Workbook

Sheet СИ_Справочник
A1: Справочник СИ — калибровочные коэффициенты и погрешности
A3: Напорные трубки (измерение динамического давления потока)
A4: Модель / зав. номер | B4: Коэфф. K_тр | C4: Погрешн. K_тр, % | D4: Примечание
A5: НИИОГАЗ 1001 | B5: 0.543 | C5: 1.83 | D5: Прямой канал, калибр. 2024
A6: НИИОГАЗ 1002 | B6: 0.538 | C6: 1.94 | D6: Прямой канал, калибр. 2024
A7: НИИОГАЗ 1003 | B7: 0.521 | C7: 2.55 | D7: Прямой канал, калибр. 2024
A8: ПИТО 2001 | B8: 0.993 | C8: 1.63 | D8: Трубка Пито, калибр. 2024
A11: Прочие СИ — относительные погрешности
A12: Группа | B12: Модель | C12: δ, % | D12: Диапазон
A13: Давление атм. | B13: Метеоскоп-М | C13: 0.14 | D13: 84–106 кПа
A14: Давление динамич. | B14: ДМЦ-01М | C14: 1.5 | D14: до 2000 Па
A15: Температура | B15: ТК-5.06 | C15: 2 | D15: −30…+250 °C
A16: Температура | B16: Полар Ex-T | C16: 2 | D16: −20…+800 °C
A17: Разрежение | B17: ВП-63 | C17: 1.5 | D17: 0–100 кПа
A18: Влажность отн. | B18: ТК-5.06 | C18: 3 | D18: 20–95 %
A19: Ротаметр | B19: Аппарат РО-6 | C19: 1 | D19: 0.5–25 л/мин
A20: Весы | B20: GH-252 | C20: 0.0001 | D20: разреш. 0.1 мг
A23: Цветовая легенда
B24: Жёлтое — вводится вручную с планшета / журнала отбора
B25: Зелёное — справочный коэффициент (неизменяемый)
B26: Оранжевое — промежуточный расчёт
B27: Ярко-зелёное — итоговый результат для протокола

Sheet Данные_отбора
A1: Данные отбора проб — ИЗАВ 0001, труба сушильной печи №1
A3: Объект | B3: АО «Пример Инжиниринг» — демо-данные для портфолио
A4: Место отбора | B4: ИЗАВ 0001 · Труба сушильной печи №1 · круглый газоход
A5: Дата / время отбора | B5: 20.04.2026 09:42–10:18 | E5: Пробы | F5: 0001пв – 0006пв
A7: Геометрия газохода (вводится на месте, с планшета)
A8: Диаметр газохода d, м | B8: 0.25
A9: Эквивалентный диаметр De, м | B9: 0.25
A10: Площадь сечения S, м² (=π·De²/4) | B10: =PI()*B9^2/4
A11: Длина прямолинейного участка L, м | B11: 3.2
A12: Толщина стенки b, м | B12: 0.005
A14: Условия окружающей среды
A15: Атмосферное давление Б, мм рт.ст. | B15: 745
A16: Температура в точке отбора t_р, °C | B16: 12
A17: Относит. влажность воздуха, % | B17: 52
A18: Разрежение у ротаметра P_р, кПа | B18: -10
A20: Параметры газопылевого потока (с приборов в точке отбора)
A21: СИ напорной трубки | B21: НИИОГАЗ 1001
A22: Динамическое давление P_д, Па | B22: 108.3
A23: Статическое давление P_ст, Па | B23: 66.1
A24: Температура газа t_г, °C | B24: 52.3
A25: Относительная влажность потока, % | B25: 6.2
A27: Данные отбора пыли (патрон АФА, сепаратор)
A28: Диаметр носика d_н, мм | B28: 6.15
A29: Время отбора τ, мин | B29: 10
A30: Масса патрона до, m₀, г | B30: 7.4986
A31: Масса патрона после, m₁, г | B31: 7.5037
A32: Скорость отбора по ротаметру W_р, л/мин | B32: 17
A34: Концентрации газов (газоанализатор, канал «Низкие»)
A35: CO, мг/м³ | B35: 125
A36: NOx, мг/м³ | B36: 82
A37: NO, мг/м³ | B37: 56
A38: NO₂, мг/м³ | B38: 26
A39: SO₂, мг/м³ | B39: 68
A41: Исполнители
A42: Пробоотборщик | B42: инженер-лаборант (подпись)
A43: Аналитик | B43: инженер-химик (подпись)

Sheet Расчёт
A1: Расчёт параметров газопылевого потока и массового выброса
A3: 1. Калибровочные коэффициенты (подтянуты из справочника по модели СИ)
A4: Модель напорной трубки | B4: =Данные_отбора!B21
A5: K_тр (коэфф. трубки) | B5: =VLOOKUP(B4,СИ_Справочник!A5:C8,2,FALSE)
A6: δK_тр, % | B6: =VLOOKUP(B4,СИ_Справочник!A5:C8,3,FALSE)
A8: 2. Исходные данные (ссылки на лист «Данные_отбора»)
A9: P_д — динамическое давление, Па | B9: =Данные_отбора!B22
A10: P_ст — статическое давление, Па | B10: =Данные_отбора!B23
A11: t_г — температура газа, °C | B11: =Данные_отбора!B24
A12: Б — атм. давление, мм рт.ст. | B12: =Данные_отбора!B15
A13: S — площадь сечения, м² | B13: =Данные_отбора!B10
A14: τ — время отбора, мин | B14: =Данные_отбора!B29
A15: Δm — масса отобр. пыли, г | B15: =Данные_отбора!B31-Данные_отбора!B30
A16: W_р — расход по ротаметру, л/мин | B16: =Данные_отбора!B32
A17: t_р — температура у ротаметра, °C | B17: =Данные_отбора!B16
A18: P_р — разрежение у ротаметра, кПа | B18: =Данные_отбора!B18
A20: 3. Основные расчёты
A21: Плотность газа при р.у. ρ_р, кг/м³ | B21: =1.293*(B12*133.3+B10)/101325*273/(273+B11)
A22: Скорость газа W, м/с =K_тр·√(2·P_д/ρ_р) | B22: =B5*SQRT(2*B9/B21)
A23: Объёмный расход при р.у. Q_р, м³/с =S·W | B23: =B13*B22
A24: Объёмный расход при н.у. Q_нy, м³/с | B24: =B23*273*(B12*133.3+B10)/(760*133.3*(273+B11))
A25: Объём отобранного газа V_ну, дм³ | B25: =B16*B14*(B18*1000+B12*133.3)*273/((273+B17)*760*133.3)
A26: Концентрация пыли Z, мг/м³ =Δm·10⁶/V_ну | B26: =B15*1000000/B25
A27: Массовый выброс пыли Ф, г/с =Z·Q_нy/1000 | B27: =B26*B24/1000
A29: 4. Расчёт расширенной неопределённости (P = 0.95)
A30: δP_д (ДМЦ-01М), % | B30: =VLOOKUP("ДМЦ-01М",СИ_Справочник!B13:C20,2,FALSE)
A31: δt_г (ТК-5.06), % | B31: =100*2/(273+B11)
A32: δБ (Метеоскоп-М), % | B32: =VLOOKUP("Метеоскоп-М",СИ_Справочник!B13:C20,2,FALSE)
A33: δP_р (ВП-63), % | B33: =VLOOKUP("ВП-63",СИ_Справочник!B13:C20,2,FALSE)
A34: δt_р (ТК-5.06), % | B34: =100*2/(273+B17)
A35: δm (весы GH-252), % | B35: =2*100*0.0001/B15
A36: δротаметр, % | B36: =VLOOKUP("Аппарат РО-6",СИ_Справочник!B13:C20,2,FALSE)
A37: δτ (СОС-пр), % | B37: =3*(1.7*0.2/(60*B14)+0.00075)*100
A39: δW (скорость), % | B39: =2*SQRT((B30/2)^2+(B31/2)^2+(B32/2)^2+(B6/2)^2+2^2)
A40: δQ_р, % | B40: =2*SQRT((B39/2)^2+1^2)
A41: δQ_нy, % | B41: =2*SQRT((B39/2)^2+1^2+(B32/2)^2+(B31/2)^2)
A42: δZ (концентрация пыли), % | B42: =2*SQRT((B35/2)^2+(B36/2)^2+(B37/2)^2+(B33/2)^2+(B34/2)^2)
A44: ΔP_д, Па =P_д · δP_д/100 | B44: =B9*B30/100
A45: ΔW, м/с | B45: =B22*B39/100
A46: ΔQ_р, м³/с | B46: =B23*B40/100
...

Sheet Итог_в_протокол
A1: Результаты измерений — готовы к переносу в протокол
A3: Протокол | C3: № 001(ПВ)-26 демо от 20.04.2026
A4: Заказчик | C4: АО «Пример Инжиниринг» (демо)
A5: Объект | C5: ИЗАВ 0001, труба сушильной печи №1
A6: Договор | C6: № 01/DEMO/2026 от 01.03.2026
A7: Акт отбора | C7: № 001(ПВ)-26 от 20.04.2026
A8: Пробы | C8: 0001пв — 0006пв
A10: Таблица №1 — Результаты определяемых показателей
A11: № | B11: Определяемый показатель | C11: Ед. изм. | D11: № пробы | E11: Результат ± Δ (P=0.95) | F11: Методика
A12: 1 | B12: Атмосферное давление | C12: кПа | D12: 0001пв | E12: =ROUND(Данные_отбора!B15*101.325/760,2)&" ± "&0.13 | F12: Метеоскоп-М · ТУ 4311-001-70203816-07
A13: 2 | B13: Температура потока | C13: °C | D13: 0002пв | E13: =ROUND(Расчёт!B11,1)&" ± "&ROUND(Расчёт!B11*Расчёт!B31/100,1) | F13: ТК-5.06 · ГОСТ 17.2.4.07-90
A14: 3 | B14: Разрежение в газоходе | C14: кПа | D14: 0003пв | E14: =ROUND(Расчёт!B10/1000,4)&" ± "&ROUND(Расчёт!B10/1000*1.5/100,4) | F14: ДМЦ-01М · ГОСТ 17.2.4.07-90
A15: 4 | B15: Скорость потока | C15: м/с | D15: 0004пв | E15: =ROUND(Расчёт!B22,2)&" ± "&ROUND(Расчёт!B45,2) | F15: ДМЦ-01М · ГОСТ 17.2.4.06-90
A16: 5 | B16: Объёмный расход (р.у.) | C16: м³/с | D16: 0005пв | E16: =ROUND(Расчёт!B23,3)&" ± "&ROUND(Расчёт!B46,3) | F16: Расчёт по ГОСТ 17.2.4.06-90
B17: Объёмный расход (н.у.) | C17: м³/с | E17: =ROUND(Расчёт!B24,3)&" ± "&ROUND(Расчёт!B47,3) | F17: Расчёт, приведено к н.у.
A18: 6 | B18: Запылённость (взвешенные частицы) | C18: мг/м³ | D18: 0006пв | E18: =ROUND(Расчёт!B26,1)&" ± "&ROUND(Расчёт!B48,1) | F18: ГОСТ 33007-2014 · гравиметрия
B19: Массовый выброс пыли | C19: г/с | D19: расчёт | E19: =ROUND(Расчёт!B27,4) | F19: Расчёт по ГОСТ 33007-2014
A20: 7 | B20: Массовая концентрация CO | C20: мг/м³ | D20: 0001пв | E20: =Данные_отбора!B35&" ± "&ROUND(Данные_отбора!B35*0.1,1) | F20: Полар Универсал Ex-T
A21: 8 | B21: Массовая концентрация NOx (в пересчёте на NO₂) | C21: мг/м³ | D21: 0002пв | E21: =Данные_отбора!B36&" ± "&ROUND(Данные_отбора!B36*0.12,1) | F21: Полар Универсал Ex-T
A22: 9 | B22: Массовая концентрация NO | C22: мг/м³ | D22: 0003пв | E22: =Данные_отбора!B37&" ± "&ROUND(Данные_отбора!B37*0.1,1) | F22: Полар Универсал Ex-T
A23: 10 | B23: Массовая концентрация NO₂ | C23: мг/м³ | D23: 0004пв | E23: =Данные_отбора!B38&" ± "&ROUND(Данные_отбора!B38*0.2,1) | F23: Полар Универсал Ex-T
A24: 11 | B24: Массовая концентрация SO₂ | C24: мг/м³ | D24: 0005пв | E24: =Данные_отбора!B39&" ± "&ROUND(Данные_отбора!B39*0.15,1) | F24: Полар Универсал Ex-T
A26: Примечание: все значения в столбце «Результат ± Δ» рассчитаны листом «Расчёт». Измените любой вход на листе «Данные_отбора» — все результаты пересчитаются автоматически.
